mplus_output/uni-05-HRS_W4.out
Mplus VERSION 8.1 (Mac)
MUTHEN & MUTHEN
05/27/2020  10:27 PM

INPUT INSTRUCTIONS

  DATA:
  FILE = "uni-05-HRS_W4.dat";

  VARIABLE:
  NAMES = mplusid UDAT UDAY UMON UYER UIWR UDWR USUB UBAK UNM1 UNM2 UNM5 UNM6;
   MISSING=.;
   CATEGORICAL ARE all; idvariable = mplusid;
  ANALYSIS:
  estimator = wlsmv; coverage=0;
  MODEL:
  g by UDAT * ;
   g by UDAY * ;
   g by UMON * ;
   g by UYER * ;
   g by UIWR * ;
   g by UDWR * ;
   g by USUB * ;
   g by UBAK * ;
   g by UNM1 * ;
   g by UNM2 * ;
   g by UNM5 * ;
   g by UNM6 * ;
   g @ 1;

  OUTPUT:
  standardized; svalues;



*** WARNING
  Data set contains cases with missing on all variables.
  These cases were not included in the analysis.
  Number of cases with missing on all variables:  907
   1 WARNING(S) FOUND IN THE INPUT INSTRUCTIONS




SUMMARY OF ANALYSIS

Number of groups                                                 1
Number of observations                                        6120

Number of dependent variables                                   12
Number of independent variables                                  0
Number of continuous latent variables                            1

Observed dependent variables

  Binary and ordered categorical (ordinal)
   UDAT        UDAY        UMON        UYER        UIWR        UDWR
   USUB        UBAK        UNM1        UNM2        UNM5        UNM6

Continuous latent variables
   G

Variables with special functions

  ID variable           MPLUSID

Estimator                                                    WLSMV
Maximum number of iterations                                  1000
Convergence criterion                                    0.500D-04
Maximum number of steepest descent iterations                   20
Maximum number of iterations for H1                           2000
Convergence criterion for H1                             0.100D-03
Parameterization                                             DELTA
Link                                                        PROBIT

Input data file(s)
  uni-05-HRS_W4.dat

Input data format  FREE


SUMMARY OF DATA

     Number of missing data patterns            90


COVARIANCE COVERAGE OF DATA

Minimum covariance coverage value   0.000


     PROPORTION OF DATA PRESENT


           Covariance Coverage
              UDAT          UDAY          UMON          UYER          UIWR
              ________      ________      ________      ________      ________
 UDAT           0.999
 UDAY           0.999         1.000
 UMON           0.997         0.997         0.997
 UYER           0.999         0.999         0.997         0.999
 UIWR           0.967         0.967         0.967         0.967         0.967
 UDWR           0.846         0.846         0.846         0.846         0.846
 USUB           0.890         0.890         0.890         0.890         0.873
 UBAK           0.971         0.972         0.971         0.971         0.949
 UNM1           0.995         0.996         0.994         0.995         0.966
 UNM2           0.970         0.970         0.969         0.970         0.943
 UNM5           0.980         0.981         0.980         0.980         0.952
 UNM6           0.937         0.937         0.937         0.937         0.910


           Covariance Coverage
              UDWR          USUB          UBAK          UNM1          UNM2
              ________      ________      ________      ________      ________
 UDWR           0.846
 USUB           0.782         0.890
 UBAK           0.835         0.887         0.972
 UNM1           0.846         0.889         0.970         0.996
 UNM2           0.829         0.871         0.948         0.968         0.970
 UNM5           0.837         0.880         0.956         0.979         0.958
 UNM6           0.802         0.846         0.916         0.936         0.923


           Covariance Coverage
              UNM5          UNM6
              ________      ________
 UNM5           0.981
 UNM6           0.933         0.937


UNIVARIATE PROPORTIONS AND COUNTS FOR CATEGORICAL VARIABLES

    UDAT
      Category 1    0.197         1202.000
      Category 2    0.803         4913.000
    UDAY
      Category 1    0.040          247.000
      Category 2    0.960         5872.000
    UMON
      Category 1    0.033          202.000
      Category 2    0.967         5902.000
    UYER
      Category 1    0.044          271.000
      Category 2    0.956         5843.000
    UIWR
      Category 1    0.001            6.000
      Category 2    0.021          125.000
      Category 3    0.065          384.000
      Category 4    0.136          806.000
      Category 5    0.207         1223.000
      Category 6    0.402         2379.000
      Category 7    0.103          611.000
      Category 8    0.040          235.000
      Category 9    0.018          105.000
      Category 10    0.008           47.000
    UDWR
      Category 1    0.007           37.000
      Category 2    0.075          390.000
      Category 3    0.132          684.000
      Category 4    0.202         1048.000
      Category 5    0.217         1124.000
      Category 6    0.275         1424.000
      Category 7    0.052          270.000
      Category 8    0.022          116.000
      Category 9    0.010           53.000
      Category 10    0.007           34.000
    USUB
      Category 1    0.051          276.000
      Category 2    0.128          700.000
      Category 3    0.097          528.000
      Category 4    0.148          807.000
      Category 5    0.211         1149.000
      Category 6    0.365         1989.000
    UBAK
      Category 1    0.052          308.000
      Category 2    0.948         5639.000
    UNM1
      Category 1    0.012           71.000
      Category 2    0.988         6023.000
    UNM2
      Category 1    0.121          718.000
      Category 2    0.879         5219.000
    UNM5
      Category 1    0.068          410.000
      Category 2    0.932         5593.000
    UNM6
      Category 1    0.284         1627.000
      Category 2    0.716         4109.000



THE MODEL ESTIMATION TERMINATED NORMALLY



MODEL FIT INFORMATION

Number of Free Parameters                       44

Chi-Square Test of Model Fit

          Value                           1974.992*
          Degrees of Freedom                    54
          P-Value                           0.0000

*   The chi-square value for MLM, MLMV, MLR, ULSMV, WLSM and WLSMV cannot be used
    for chi-square difference testing in the regular way.  MLM, MLR and WLSM
    chi-square difference testing is described on the Mplus website.  MLMV, WLSMV,
    and ULSMV difference testing is done using the DIFFTEST option.

RMSEA (Root Mean Square Error Of Approximation)

          Estimate                           0.076
          90 Percent C.I.                    0.073  0.079
          Probability RMSEA <= .05           0.000

CFI/TLI

          CFI                                0.934
          TLI                                0.919

Chi-Square Test of Model Fit for the Baseline Model

          Value                          29111.316
          Degrees of Freedom                    66
          P-Value                           0.0000

SRMR (Standardized Root Mean Square Residual)

          Value                              0.103

Optimum Function Value for Weighted Least-Squares Estimator

          Value                     0.13294380D+00



MODEL RESULTS

                                                    Two-Tailed
                    Estimate       S.E.  Est./S.E.    P-Value

 G        BY
    UDAT               0.482      0.017     29.099      0.000
    UDAY               0.608      0.025     24.423      0.000
    UMON               0.727      0.026     28.187      0.000
    UYER               0.781      0.020     38.801      0.000
    UIWR               0.851      0.008    105.421      0.000
    UDWR               0.863      0.009     95.956      0.000
    USUB               0.405      0.013     30.520      0.000
    UBAK               0.507      0.026     19.181      0.000
